Workbook

Sheet README
A1: JLR: The Business Case for Cyber Resilience. Deliverable 6: Expected-loss and investment model
A3: Purpose | B3: Compares four ways to spend a resilience budget (A prevention-first, B recovery-first, C risk transfer, D recovery-led blend) by the expected loss each avoids over three years, against its cost.
A4: Status | B4: Independent portfolio analysis using public information only. Not affiliated with or endorsed by JLR or Tata Motors. Every programme cost, probability and saving is an ILLUSTRATIVE ASSUMPTION unless a source is shown. Treat results as a way to see what must be true, not as a forecast.
A5: How to use | B5: Change only the blue cells on the Inputs sheet. Every other sheet recalculates. Yellow cells are the assumptions that matter most.
A6: Colour code | B6: Blue text = input you can change. Black text = formula. Green text = link to another sheet. Yellow fill = key assumption.
A7: Sheets | B7: Inputs: all assumptions with sources. Model: the calculation, one block per scenario. Summary: results and chart. Sensitivity: what moves the answer. Checks: tests that the model reconciles. Sources: where each fact comes from (numbers match the Source Log, Deliverable 1).
A8: Method | B8: For each scenario: loss if a JLR-scale cyber event happens = weeks of lost output x weekly revenue x margin on lost revenue + exceptional cost. A programme can change the probability of the event, the weeks lost, and (for insurance) the part of the loss recovered. Expected loss = probability x loss. Net expected benefit = expected loss avoided minus three-year cost. No discounting (three years, illustrative).
A9: Limits | B9: Public information gives no programme costs or attack probabilities, so those are placeholders that the board should replace. Revenue is not profit: the margin input converts lost revenue to lost profit. Supplier and wider UK losses are not counted.

Sheet Summary
A1: Summary: what each option is worth over three years (£m)
A2: All values link to the Model sheet and update when Inputs change. Illustrative assumptions.
A4: Net expected benefit (avoided loss minus cost), £m | B4: Lower risk | C4: Central | D4: Higher risk
A5: A Prevention-first | B5: =Model!C19 -> -138.23712 | C5: =Model!C42 -> -99.613846 | D5: =Model!C65 -> -4.9442308
A6: B Recovery-first | B6: =Model!D19 -> -76.192308 | C6: =Model!D42 -> -39.384615 | D6: =Model!D65 -> 72.307692
A7: C Risk transfer | B7: =Model!E19 -> -37.5 | C7: =Model!E42 -> -22.5 | D7: =Model!E65 -> 0
A8: D Recovery-led blend | B8: =Model!F19 -> -123.37423 | C8: =Model!F42 -> -68.912308 | D8: =Model!F65 -> 74.573077
A9: Best option on this measure | B9: =IF(MAX(B5:B8)<=0,"None pays back",INDEX($A$5:$A$8,MATCH(MAX(B5:B8),B5:B8,0))) -> None pays back | C9: =IF(MAX(C5:C8)<=0,"None pays back",INDEX($A$5:$A$8,MATCH(MAX(C5:C8),C5:C8,0))) -> None pays back | D9: =IF(MAX(D5:D8)<=0,"None pays back",INDEX($A$5:$A$8,MATCH(MAX(D5:D8),D5:D8,0))) -> D Recovery-led blend
A11: Expected loss avoided, £m | B11: Lower risk | C11: Central | D11: Higher risk
A12: A Prevention-first | B12: =Model!C17 -> 11.762885 | C12: =Model!C40 -> 50.386154 | D12: =Model!C63 -> 145.05577
A13: B Recovery-first | B13: =Model!D17 -> 3.8076923 | C13: =Model!D40 -> 40.615385 | D13: =Model!D63 -> 152.30769
A14: C Risk transfer | B14: =Model!E17 -> 7.5 | C14: =Model!E40 -> 22.5 | D14: =Model!E63 -> 45
A15: D Recovery-led blend | B15: =Model!F17 -> 11.625769 | C15: =Model!F40 -> 66.087692 | D15: =Model!F63 -> 209.57308
A17: Three-year cost, £m (input) | B17: Cost
A18: A Prevention-first | B18: =Inputs!C23 -> 150
A19: B Recovery-first | B19: =Inputs!D23 -> 80
A20: C Risk transfer | B20: =Inputs!E23 -> 45
A21: D Recovery-led blend | B21: =Inputs!F23 -> 135
A23: Break-even probability of a cyber event (central inputs) | B23: Break-even | C23: Central assumption
A24: A Prevention-first | B24: =Model!C45 -> 0.44655125 | C24: =Inputs!D6 -> 0.15
A25: B Recovery-first | B25: =Model!D45 -> 0.34393939 | C25: =Inputs!D6 -> 0.15
A26: C Risk transfer | B26: =Model!E45 -> 0.3 | C26: =Inputs!D6 -> 0.15
A27: D Recovery-led blend | B27: =Model!F45 -> 0.33480485 | C27: =Inputs!D6 -> 0.15
A28: Above 100% means the option cannot pay back on expected profit at any probability.
A30: If the cyber event happens (central), £m | B30: Do nothing | C30: A | D30: B | E30: C | F30: D
A31: Net event loss after insurance | B31: =Model!B35 -> 1001.2308 | C31: =Model!C35 -> 950.46154 | D31: =Model!D35 -> 798.15385 | E31: =Model!E35 -> 851.23077 | F31: =Model!F35 -> 698.15385
A32: Reduction compared with doing nothing | C32: =Model!C44 -> 50.769231 | D32: =Model!D44 -> 203.07692 | E32: =Model!E44 -> 150 | F32: =Model!F44 -> 303.07692
A33: Net event loss as % of FY25 profit before tax | B33: =Model!B46 -> 0.40049231 | C33: =Model!C46 -> 0.38018462 | D33: =Model!D46 -> 0.31926154 | E33: =Model!E46 -> 0.34049231 | F33: =Model!F46 -> 0.27926154

Sheet Inputs
A1: Inputs and assumptions (£m unless stated)
A2: Blue = edit me. Yellow = key assumption. All programme costs, probabilities and savings are illustrative assumptions, not JLR figures.
A4: Scenario inputs | B4: Unit | C4: Lower risk | D4: Central | E4: Higher risk | G4: Basis (source numbers match Deliverable 1)
A5: Scenario inputs
A6: Probability of a JLR-scale cyber event within 3 years | B6: % | C6: 0.05 | D6: 0.15 | E6: 0.3 | G6: ASSUMPTION. No public source gives this. NCSC reports nationally significant incidents rose from 89 to 204 in a year [10], which argues against very low values. Tested widely.
A7: Probability of a non-cyber outage of similar length within 3 years | B7: % | C7: 0 | D7: 0.05 | E7: 0.1 | G7: ASSUMPTION. Recovery capability (B, D) also helps here; prevention and insurance do not.
A8: Margin on lost revenue (profit lost per £ of revenue) | B8: % | C8: 0.15 | D8: 0.2 | E8: 0.25 | G8: ASSUMPTION. Lost revenue is not lost profit; some costs fall when output stops. Deliverable 4 note.
A9: Weeks of output lost without the programme | B9: weeks | C9: 6.3 | D9: 7.3 | E9: 8.9 | G9: Deliverable 4: 7.3 weeks (Q1 FY26 run rate); 6.3 and 8.9 weeks are its 5% baseline and Q4 baseline tests. Derived from [23][24][26].
A10: Weeks saved by a recovery programme (B and D) | B10: weeks | C10: 1 | D10: 2 | E10: 3 | G10: ASSUMPTION. Deliverable 5 break-even table tests 1, 2 and 3 weeks. Maersk rebuilt in 10 days [30]; JLR's own saving is unknown.
A12: Common inputs (same in every scenario; value in column D)
A13: Q1 FY26 revenue (pre-attack run rate) | B13: £m | D13: 6600 | G13: Derived: H1 revenue £11.5bn less Q2 £4.9bn [7][25][26]. Used in Deliverable 4.
A14: Weeks in a quarter | B14: weeks | D14: 13 | G14: Arithmetic.
A15: Revenue per week | B15: £m | D15: =D13/D14 -> 507.69231 | G15: Formula. Deliverable 4: about £0.51bn a week.
A16: Exceptional cyber cost per event | B16: £m | D16: 260 | G16: JLR Annual Report 2025/26: exceptional cyber items £260m for the full year [26]; Insurance Business says none was recovered [28].
A17: Insurance recovery rate (share of event loss paid, up to the limit) | B17: % | D17: 0.33 | G17: M&S could claim up to £100m against a profit hit of about £300m [28]. Norsk Hydro's first payout was about 6% of losses [29]. Tested 0% to 50% on Sensitivity.
A18: FY25 profit before tax and exceptional items (context) | B18: £m | D18: 2500 | G18: JLR FY25 results release [20]; used only to size the event loss.
A19: Liquidity at 31 March 2026 (context) | B19: £m | D19: 6900 | G19: JLR Annual Report 2025/26 [26].
A21: Option parameters | B21: Unit | C21: A Prevention-first | D21: B Recovery-first | E21: C Risk transfer | F21: D Recovery-led blend | G21: Basis
A22: Each option (columns C to F)
A23: Three-year programme cost | B23: £m | C23: 150 | D23: 80 | E23: 45 | F23: 135 | G23: ASSUMPTION (placeholder). A: broad programme. B: recovery capability. C: premiums for a £150m limit. D: B plus £25m targeted prevention plus premiums for a £100m limit. Tested 0.5x to 1.5x.
A24: Relative cut in cyber event probability | B24: % | C24: 0.3 | D24: 0 | E24: 0 | F24: 0.1 | G24: ASSUMPTION. Prevention lowers the odds but cannot remove them [10][27]. D includes only targeted prevention.
A25: Share of the weeks-saved input that the option achieves | B25: % | C25: 0.25 | D25: 1 | E25: 0 | F25: 1 | G25: ASSUMPTION. Only recovery capability (B, D) shortens the stop; prevention helps a little.
A26: Recovery capability also helps non-cyber outages (1 = yes) | B26: flag | C26: 0 | D26: 1 | E26: 0 | F26: 1 | G26: Design logic from Deliverable 5 criterion 3.
A27: Insurance limit | B27: £m | C27: 0 | D27: 0 | E27: 150 | F27: 100 | G27: ASSUMPTION. M&S had £100m of cover [28]. JLR had none in force [28].

Sheet Model
A1: Model: loss, expected loss and net benefit by scenario (£m)
A2: All cells are formulas. Edit the Inputs sheet only. Columns: Do nothing, then options A to D.
A4: Scenario: Lower risk
A5: £m unless stated | B5: Do nothing | C5: A Prevention-first | D5: B Recovery-first | E5: C Risk transfer | F5: D Recovery-led blend
A6: Probability of a cyber event within 3 years | B6: =Inputs!C$6 -> 0.05 | C6: =Inputs!C$6*(1-Inputs!C$24) -> 0.035 | D6: =Inputs!C$6*(1-Inputs!D$24) -> 0.05 | E6: =Inputs!C$6*(1-Inputs!E$24) -> 0.05 | F6: =Inputs!C$6*(1-Inputs!F$24) -> 0.045
A7: Weeks of output lost if the event happens | B7: =Inputs!C$9 -> 6.3 | C7: =Inputs!C$9-Inputs!C$10*Inputs!C$25 -> 6.05 | D7: =Inputs!C$9-Inputs!C$10*Inputs!D$25 -> 5.3 | E7: =Inputs!C$9-Inputs!C$10*Inputs!E$25 -> 6.3 | F7: =Inputs!C$9-Inputs!C$10*Inputs!F$25 -> 5.3
A8: Lost profit if the event happens | B8: =B7*Inputs!$D$15*Inputs!C$8 -> 479.76923 | C8: =C7*Inputs!$D$15*Inputs!C$8 -> 460.73077 | D8: =D7*Inputs!$D$15*Inputs!C$8 -> 403.61538 | E8: =E7*Inputs!$D$15*Inputs!C$8 -> 479.76923 | F8: =F7*Inputs!$D$15*Inputs!C$8 -> 403.61538
A9: Exceptional cyber cost | B9: =Inputs!$D$16 -> 260 | C9: =Inputs!$D$16 -> 260 | D9: =Inputs!$D$16 -> 260 | E9: =Inputs!$D$16 -> 260 | F9: =Inputs!$D$16 -> 260
A10: Total event loss before insurance | B10: =B8+B9 -> 739.76923 | C10: =C8+C9 -> 720.73077 | D10: =D8+D9 -> 663.61538 | E10: =E8+E9 -> 739.76923 | F10: =F8+F9 -> 663.61538
A11: Insurance recovery | B11: 0 | C11: =MIN(Inputs!C$27,Inputs!$D$17*C10) -> 0 | D11: =MIN(Inputs!D$27,Inputs!$D$17*D10) -> 0 | E11: =MIN(Inputs!E$27,Inputs!$D$17*E10) -> 150 | F11: =MIN(Inputs!F$27,Inputs!$D$17*F10) -> 100
A12: Net event loss after insurance | B12: =B10-B11 -> 739.76923 | C12: =C10-C11 -> 720.73077 | D12: =D10-D11 -> 663.61538 | E12: =E10-E11 -> 589.76923 | F12: =F10-F11 -> 563.61538
A13: Expected cyber loss over 3 years | B13: =B6*B12 -> 36.988462 | C13: =C6*C12 -> 25.225577 | D13: =D6*D12 -> 33.180769 | E13: =E6*E12 -> 29.488462 | F13: =F6*F12 -> 25.362692
A14: Weeks lost in a non-cyber outage | B14: =Inputs!C$9 -> 6.3 | C14: =Inputs!C$9-Inputs!C$10*Inputs!C$25*Inputs!C$26 -> 6.3 | D14: =Inputs!C$9-Inputs!C$10*Inputs!D$25*Inputs!D$26 -> 5.3 | E14: =Inputs!C$9-Inputs!C$10*Inputs!E$25*Inputs!E$26 -> 6.3 | F14: =Inputs!C$9-Inputs!C$10*Inputs!F$25*Inputs!F$26 -> 5.3
A15: Expected non-cyber loss over 3 years | B15: =Inputs!C$7*B14*Inputs!$D$15*Inputs!C$8 -> 0 | C15: =Inputs!C$7*C14*Inputs!$D$15*Inputs!C$8 -> 0 | D15: =Inputs!C$7*D14*Inputs!$D$15*Inputs!C$8 -> 0 | E15: =Inputs!C$7*E14*Inputs!$D$15*Inputs!C$8 -> 0 | F15: =Inputs!C$7*F14*Inputs!$D$15*Inputs!C$8 -> 0
A16: Expected total loss over 3 years | B16: =B13+B15 -> 36.988462 | C16: =C13+C15 -> 25.225577 | D16: =D13+D15 -> 33.180769 | E16: =E13+E15 -> 29.488462 | F16: =F13+F15 -> 25.362692
A17: Expected loss avoided vs do nothing | C17: =$B16-C16 -> 11.762885 | D17: =$B16-D16 -> 3.8076923 | E17: =$B16-E16 -> 7.5 | F17: =$B16-F16 -> 11.625769
A18: Three-year programme cost | B18: 0 | C18: =Inputs!C$23 -> 150 | D18: =Inputs!D$23 -> 80 | E18: =Inputs!E$23 -> 45 | F18: =Inputs!F$23 -> 135
A19: Net expected benefit (avoided loss minus cost) | C19: =C17-C18 -> -138.23712 | D19: =D17-D18 -> -76.192308 | E19: =E17-E18 -> -37.5 | F19: =F17-F18 -> -123.37423
A20: Benefit-to-cost ratio | C20: =IF(C18=0,"n/a",C17/C18) -> 0.078419231 | D20: =IF(D18=0,"n/a",D17/D18) -> 0.047596154 | E20: =IF(E18=0,"n/a",E17/E18) -> 0.16666667 | F20: =IF(F18=0,"n/a",F17/F18) -> 0.086116809
A21: Reduction in net loss if the event happens | C21: =$B12-C12 -> 19.038462 | D21: =$B12-D12 -> 76.153846 | E21: =$B12-E12 -> 150 | F21: =$B12-F12 -> 176.15385
A22: Break-even probability of the cyber event | C22: =IF(($B12-(1-Inputs!C$24)*C12)<=0,"n/a",MAX(0,C18-($B15-C15))/($B12-(1-Inputs!C$24)*C12)) -> 0.63759871 | D22: =IF(($B12-(1-Inputs!D$24)*D12)<=0,"n/a",MAX(0,D18-($B15-D15))/($B12-(1-Inputs!D$24)*D12)) -> 1.0505051 | E22: =IF(($B12-(1-Inputs!E$24)*E12)<=0,"n/a",MAX(0,E18-($B15-E15))/($B12-(1-Inputs!E$24)*E12)) -> 0.3 | F22: =IF(($B12-(1-Inputs!F$24)*F12)<=0,"n/a",MAX(0,F18-($B15-F15))/($B12-(1-Inputs!F$24)*F12)) -> 0.58060674
A23: Net event loss as % of FY25 profit before tax | B23: =B12/Inputs!$D$18 -> 0.29590769 | C23: =C12/Inputs!$D$18 -> 0.28829231 | D23: =D12/Inputs!$D$18 -> 0.26544615 | E23: =E12/Inputs!$D$18 -> 0.23590769 | F23: =F12/Inputs!$D$18 -> 0.22544615
A27: Scenario: Central
A28: £m unless stated | B28: Do nothing | C28: A Prevention-first | D28: B Recovery-first | E28: C Risk transfer | F28: D Recovery-led blend
A29: Probability of a cyber event within 3 years | B29: =Inputs!D$6 -> 0.15 | C29: =Inputs!D$6*(1-Inputs!C$24) -> 0.105 | D29: =Inputs!D$6*(1-Inputs!D$24) -> 0.15 | E29: =Inputs!D$6*(1-Inputs!E$24) -> 0.15 | F29: =Inputs!D$6*(1-Inputs!F$24) -> 0.135
A30: Weeks of output lost if the event happens | B30: =Inputs!D$9 -> 7.3 | C30: =Inputs!D$9-Inputs!D$10*Inputs!C$25 -> 6.8 | D30: =Inputs!D$9-Inputs!D$10*Inputs!D$25 -> 5.3 | E30: =Inputs!D$9-Inputs!D$10*Inputs!E$25 -> 7.3 | F30: =Inputs!D$9-Inputs!D$10*Inputs!F$25 -> 5.3
A31: Lost profit if the event happens | B31: =B30*Inputs!$D$15*Inputs!D$8 -> 741.23077 | C31: =C30*Inputs!$D$15*Inputs!D$8 -> 690.46154 | D31: =D30*Inputs!$D$15*Inputs!D$8 -> 538.15385 | E31: =E30*Inputs!$D$15*Inputs!D$8 -> 741.23077 | F31: =F30*Inputs!$D$15*Inputs!D$8 -> 538.15385
A32: Exceptional cyber cost | B32: =Inputs!$D$16 -> 260 | C32: =Inputs!$D$16 -> 260 | D32: =Inputs!$D$16 -> 260 | E32: =Inputs!$D$16 -> 260 | F32: =Inputs!$D$16 -> 260
A33: Total event loss before insurance | B33: =B31+B32 -> 1001.2308 | C33: =C31+C32 -> 950.46154 | D33: =D31+D32 -> 798.15385 | E33: =E31+E32 -> 1001.2308 | F33: =F31+F32 -> 798.15385
A34: Insurance recovery | B34: 0 | C34: =MIN(Inputs!C$27,Inputs!$D$17*C33) -> 0 | D34: =MIN(Inputs!D$27,Inputs!$D$17*D33) -> 0 | E34: =MIN(Inputs!E$27,Inputs!$D$17*E33) -> 150 | F34: =MIN(Inputs!F$27,Inputs!$D$17*F33) -> 100
A35: Net event loss after insurance | B35: =B33-B34 -> 1001.2308 | C35: =C33-C34 -> 950.46154 | D35: =D33-D34 -> 798.15385 | E35: =E33-E34 -> 851.23077 | F35: =F33-F34 -> 698.15385
A36: Expected cyber loss over 3 years | B36: =B29*B35 -> 150.18462 | C36: =C29*C35 -> 99.798462 | D36: =D29*D35 -> 119.72308 | E36: =E29*E35 -> 127.68462 | F36: =F29*F35 -> 94.250769
A37: Weeks lost in a non-cyber outage | B37: =Inputs!D$9 -> 7.3 | C37: =Inputs!D$9-Inputs!D$10*Inputs!C$25*Inputs!C$26 -> 7.3 | D37: =Inputs!D$9-Inputs!D$10*Inputs!D$25*Inputs!D$26 -> 5.3 | E37: =Inputs!D$9-Inputs!D$10*Inputs!E$25*Inputs!E$26 -> 7.3 | F37: =Inputs!D$9-Inputs!D$10*Inputs!F$25*Inputs!F$26 -> 5.3
A38: Expected non-cyber loss over 3 years | B38: =Inputs!D$7*B37*Inputs!$D$15*Inputs!D$8 -> 37.061538 | C38: =Inputs!D$7*C37*Inputs!$D$15*Inputs!D$8 -> 37.061538 | D38: =Inputs!D$7*D37*Inputs!$D$15*Inputs!D$8 -> 26.907692 | E38: =Inputs!D$7*E37*Inputs!$D$15*Inputs!D$8 -> 37.061538 | F38: =Inputs!D$7*F37*Inputs!$D$15*Inputs!D$8 -> 26.907692
A39: Expected total loss over 3 years | B39: =B36+B38 -> 187.24615 | C39: =C36+C38 -> 136.86 | D39: =D36+D38 -> 146.63077 | E39: =E36+E38 -> 164.74615 | F39: =F36+F38 -> 121.15846
A40: Expected loss avoided vs do nothing | C40: =$B39-C39 -> 50.386154 | D40: =$B39-D39 -> 40.615385 | E40: =$B39-E39 -> 22.5 | F40: =$B39-F39 -> 66.087692
A41: Three-year programme cost | B41: 0 | C41: =Inputs!C$23 -> 150 | D41: =Inputs!D$23 -> 80 | E41: =Inputs!E$23 -> 45 | F41: =Inputs!F$23 -> 135
A42: Net expected benefit (avoided loss minus cost) | C42: =C40-C41 -> -99.613846 | D42: =D40-D41 -> -39.384615 | E42: =E40-E41 -> -22.5 | F42: =F40-F41 -> -68.912308
A43: Benefit-to-cost ratio | C43: =IF(C41=0,"n/a",C40/C41) -> 0.33590769 | D43: =IF(D41=0,"n/a",D40/D41) -> 0.50769231 | E43: =IF(E41=0,"n/a",E40/E41) -> 0.5 | F43: =IF(F41=0,"n/a",F40/F41) -> 0.48953846
A44: Reduction in net loss if the event happens | C44: =$B35-C35 -> 50.769231 | D44: =$B35-D35 -> 203.07692 | E44: =$B35-E35 -> 150 | F44: =$B35-F35 -> 303.07692
...

Sheet Sensitivity
A1: Sensitivity: what moves the answer (central inputs unless stated)
A3: 1. Option B net expected benefit (£m): probability of cyber event (rows) by weeks saved (columns)
A4: Probability \ weeks saved | B4: 0.5 | C4: 1 | D4: 1.5 | E4: 2 | F4: 2.5 | G4: 3 | H4: 4
A5: 0.05 | B5: =B$4*Inputs!$D$15*Inputs!$D$8*($A5+Inputs!$D$7)-Inputs!$D$23 -> -74.923077 | C5: =C$4*Inputs!$D$15*Inputs!$D$8*($A5+Inputs!$D$7)-Inputs!$D$23 -> -69.846154 | D5: =D$4*Inputs!$D$15*Inputs!$D$8*($A5+Inputs!$D$7)-Inputs!$D$23 -> -64.769231 | E5: =E$4*Inputs!$D$15*Inputs!$D$8*($A5+Inputs!$D$7)-Inputs!$D$23 -> -59.692308 | F5: =F$4*Inputs!$D$15*Inputs!$D$8*($A5+Inputs!$D$7)-Inputs!$D$23 -> -54.615385 | G5: =G$4*Inputs!$D$15*Inputs!$D$8*($A5+Inputs!$D$7)-Inputs!$D$23 -> -49.538462 | H5: =H$4*Inputs!$D$15*Inputs!$D$8*($A5+Inputs!$D$7)-Inputs!$D$23 -> -39.384615
A6: 0.1 | B6: =B$4*Inputs!$D$15*Inputs!$D$8*($A6+Inputs!$D$7)-Inputs!$D$23 -> -72.384615 | C6: =C$4*Inputs!$D$15*Inputs!$D$8*($A6+Inputs!$D$7)-Inputs!$D$23 -> -64.769231 | D6: =D$4*Inputs!$D$15*Inputs!$D$8*($A6+Inputs!$D$7)-Inputs!$D$23 -> -57.153846 | E6: =E$4*Inputs!$D$15*Inputs!$D$8*($A6+Inputs!$D$7)-Inputs!$D$23 -> -49.538462 | F6: =F$4*Inputs!$D$15*Inputs!$D$8*($A6+Inputs!$D$7)-Inputs!$D$23 -> -41.923077 | G6: =G$4*Inputs!$D$15*Inputs!$D$8*($A6+Inputs!$D$7)-Inputs!$D$23 -> -34.307692 | H6: =H$4*Inputs!$D$15*Inputs!$D$8*($A6+Inputs!$D$7)-Inputs!$D$23 -> -19.076923
A7: 0.15 | B7: =B$4*Inputs!$D$15*Inputs!$D$8*($A7+Inputs!$D$7)-Inputs!$D$23 -> -69.846154 | C7: =C$4*Inputs!$D$15*Inputs!$D$8*($A7+Inputs!$D$7)-Inputs!$D$23 -> -59.692308 | D7: =D$4*Inputs!$D$15*Inputs!$D$8*($A7+Inputs!$D$7)-Inputs!$D$23 -> -49.538462 | E7: =E$4*Inputs!$D$15*Inputs!$D$8*($A7+Inputs!$D$7)-Inputs!$D$23 -> -39.384615 | F7: =F$4*Inputs!$D$15*Inputs!$D$8*($A7+Inputs!$D$7)-Inputs!$D$23 -> -29.230769 | G7: =G$4*Inputs!$D$15*Inputs!$D$8*($A7+Inputs!$D$7)-Inputs!$D$23 -> -19.076923 | H7: =H$4*Inputs!$D$15*Inputs!$D$8*($A7+Inputs!$D$7)-Inputs!$D$23 -> 1.2307692
A8: 0.2 | B8: =B$4*Inputs!$D$15*Inputs!$D$8*($A8+Inputs!$D$7)-Inputs!$D$23 -> -67.307692 | C8: =C$4*Inputs!$D$15*Inputs!$D$8*($A8+Inputs!$D$7)-Inputs!$D$23 -> -54.615385 | D8: =D$4*Inputs!$D$15*Inputs!$D$8*($A8+Inputs!$D$7)-Inputs!$D$23 -> -41.923077 | E8: =E$4*Inputs!$D$15*Inputs!$D$8*($A8+Inputs!$D$7)-Inputs!$D$23 -> -29.230769 | F8: =F$4*Inputs!$D$15*Inputs!$D$8*($A8+Inputs!$D$7)-Inputs!$D$23 -> -16.538462 | G8: =G$4*Inputs!$D$15*Inputs!$D$8*($A8+Inputs!$D$7)-Inputs!$D$23 -> -3.8461538 | H8: =H$4*Inputs!$D$15*Inputs!$D$8*($A8+Inputs!$D$7)-Inputs!$D$23 -> 21.538462
A9: 0.25 | B9: =B$4*Inputs!$D$15*Inputs!$D$8*($A9+Inputs!$D$7)-Inputs!$D$23 -> -64.769231 | C9: =C$4*Inputs!$D$15*Inputs!$D$8*($A9+Inputs!$D$7)-Inputs!$D$23 -> -49.538462 | D9: =D$4*Inputs!$D$15*Inputs!$D$8*($A9+Inputs!$D$7)-Inputs!$D$23 -> -34.307692 | E9: =E$4*Inputs!$D$15*Inputs!$D$8*($A9+Inputs!$D$7)-Inputs!$D$23 -> -19.076923 | F9: =F$4*Inputs!$D$15*Inputs!$D$8*($A9+Inputs!$D$7)-Inputs!$D$23 -> -3.8461538 | G9: =G$4*Inputs!$D$15*Inputs!$D$8*($A9+Inputs!$D$7)-Inputs!$D$23 -> 11.384615 | H9: =H$4*Inputs!$D$15*Inputs!$D$8*($A9+Inputs!$D$7)-Inputs!$D$23 -> 41.846154
A10: 0.3 | B10: =B$4*Inputs!$D$15*Inputs!$D$8*($A10+Inputs!$D$7)-Inputs!$D$23 -> -62.230769 | C10: =C$4*Inputs!$D$15*Inputs!$D$8*($A10+Inputs!$D$7)-Inputs!$D$23 -> -44.461538 | D10: =D$4*Inputs!$D$15*Inputs!$D$8*($A10+Inputs!$D$7)-Inputs!$D$23 -> -26.692308 | E10: =E$4*Inputs!$D$15*Inputs!$D$8*($A10+Inputs!$D$7)-Inputs!$D$23 -> -8.9230769 | F10: =F$4*Inputs!$D$15*Inputs!$D$8*($A10+Inputs!$D$7)-Inputs!$D$23 -> 8.8461538 | G10: =G$4*Inputs!$D$15*Inputs!$D$8*($A10+Inputs!$D$7)-Inputs!$D$23 -> 26.615385 | H10: =H$4*Inputs!$D$15*Inputs!$D$8*($A10+Inputs!$D$7)-Inputs!$D$23 -> 62.153846
A11: 0.4 | B11: =B$4*Inputs!$D$15*Inputs!$D$8*($A11+Inputs!$D$7)-Inputs!$D$23 -> -57.153846 | C11: =C$4*Inputs!$D$15*Inputs!$D$8*($A11+Inputs!$D$7)-Inputs!$D$23 -> -34.307692 | D11: =D$4*Inputs!$D$15*Inputs!$D$8*($A11+Inputs!$D$7)-Inputs!$D$23 -> -11.461538 | E11: =E$4*Inputs!$D$15*Inputs!$D$8*($A11+Inputs!$D$7)-Inputs!$D$23 -> 11.384615 | F11: =F$4*Inputs!$D$15*Inputs!$D$8*($A11+Inputs!$D$7)-Inputs!$D$23 -> 34.230769 | G11: =G$4*Inputs!$D$15*Inputs!$D$8*($A11+Inputs!$D$7)-Inputs!$D$23 -> 57.076923 | H11: =H$4*Inputs!$D$15*Inputs!$D$8*($A11+Inputs!$D$7)-Inputs!$D$23 -> 102.76923
A14: 2. Break-even probability of a cyber event: cost (rows) by weeks saved (columns). Cost ÷ (weeks saved x weekly profit). Ignores non-cyber benefit.
A15: Cost £m \ weeks saved | B15: 1 | C15: 2 | D15: 3
A16: 50 | B16: =$A16/(B$15*Inputs!$D$15*Inputs!$D$8) -> 0.49242424 | C16: =$A16/(C$15*Inputs!$D$15*Inputs!$D$8) -> 0.24621212 | D16: =$A16/(D$15*Inputs!$D$15*Inputs!$D$8) -> 0.16414141
A17: 100 | B17: =$A17/(B$15*Inputs!$D$15*Inputs!$D$8) -> 0.98484848 | C17: =$A17/(C$15*Inputs!$D$15*Inputs!$D$8) -> 0.49242424 | D17: =$A17/(D$15*Inputs!$D$15*Inputs!$D$8) -> 0.32828283
A18: 200 | B18: =$A18/(B$15*Inputs!$D$15*Inputs!$D$8) -> 1.969697 | C18: =$A18/(C$15*Inputs!$D$15*Inputs!$D$8) -> 0.98484848 | D18: =$A18/(D$15*Inputs!$D$15*Inputs!$D$8) -> 0.65656566
A21: 3. Insurance recovery rate: net expected benefit (£m) of C and D
A22: Recovery rate | B22: C Risk transfer | C22: D Recovery-led blend
A23: 0 | B23: =Inputs!$D$6*MIN(Inputs!$E$27,$A23*Model!$B$33)-Inputs!$E$23 -> -45 | C23: =(Inputs!$D$6*Model!$B$33-Model!$F$29*(Model!$F$33-MIN(Inputs!$F$27,$A23*Model!$F$33)))+(Model!$B$38-Model!$F$38)-Inputs!$F$23 -> -82.412308
A24: 0.06 | B24: =Inputs!$D$6*MIN(Inputs!$E$27,$A24*Model!$B$33)-Inputs!$E$23 -> -35.988923 | C24: =(Inputs!$D$6*Model!$B$33-Model!$F$29*(Model!$F$33-MIN(Inputs!$F$27,$A24*Model!$F$33)))+(Model!$B$38-Model!$F$38)-Inputs!$F$23 -> -75.947262
A25: 0.33 | B25: =Inputs!$D$6*MIN(Inputs!$E$27,$A25*Model!$B$33)-Inputs!$E$23 -> -22.5 | C25: =(Inputs!$D$6*Model!$B$33-Model!$F$29*(Model!$F$33-MIN(Inputs!$F$27,$A25*Model!$F$33)))+(Model!$B$38-Model!$F$38)-Inputs!$F$23 -> -68.912308
A26: 0.5 | B26: =Inputs!$D$6*MIN(Inputs!$E$27,$A26*Model!$B$33)-Inputs!$E$23 -> -22.5 | C26: =(Inputs!$D$6*Model!$B$33-Model!$F$29*(Model!$F$33-MIN(Inputs!$F$27,$A26*Model!$F$33)))+(Model!$B$38-Model!$F$38)-Inputs!$F$23 -> -68.912308
A27: 0% = no recovery; 6% = Norsk Hydro first payout [29]; 33% = M&S cover against profit hit [28]; 50% = optimistic.
A29: 4. Programme cost multiplier: net expected benefit (£m) of B and D
A30: Cost multiplier | B30: B Recovery-first | C30: D Recovery-led blend
A31: 0.5 | B31: =Model!$D$40-$A31*Inputs!$D$23 -> 0.61538462 | C31: =Model!$F$40-$A31*Inputs!$F$23 -> -1.4123077
A32: 0.75 | B32: =Model!$D$40-$A32*Inputs!$D$23 -> -19.384615 | C32: =Model!$F$40-$A32*Inputs!$F$23 -> -35.162308
A33: 1 | B33: =Model!$D$40-$A33*Inputs!$D$23 -> -39.384615 | C33: =Model!$F$40-$A33*Inputs!$F$23 -> -68.912308
A34: 1.25 | B34: =Model!$D$40-$A34*Inputs!$D$23 -> -59.384615 | C34: =Model!$F$40-$A34*Inputs!$F$23 -> -102.66231
A35: 1.5 | B35: =Model!$D$40-$A35*Inputs!$D$23 -> -79.384615 | C35: =Model!$F$40-$A35*Inputs!$F$23 -> -136.41231
A38: 5. Margin on lost revenue: net expected benefit (£m) of B (central probability, 2 weeks saved)
A39: Margin | B39: B Recovery-first
A40: 0.1 | B40: =Inputs!$D$10*Inputs!$D$15*$A40*(Inputs!$D$6+Inputs!$D$7)-Inputs!$D$23 -> -59.692308
A41: 0.15 | B41: =Inputs!$D$10*Inputs!$D$15*$A41*(Inputs!$D$6+Inputs!$D$7)-Inputs!$D$23 -> -49.538462
A42: 0.2 | B42: =Inputs!$D$10*Inputs!$D$15*$A42*(Inputs!$D$6+Inputs!$D$7)-Inputs!$D$23 -> -39.384615
A43: 0.25 | B43: =Inputs!$D$10*Inputs!$D$15*$A43*(Inputs!$D$6+Inputs!$D$7)-Inputs!$D$23 -> -29.230769
A44: 0.3 | B44: =Inputs!$D$10*Inputs!$D$15*$A44*(Inputs!$D$6+Inputs!$D$7)-Inputs!$D$23 -> -19.076923

Sheet Checks
A1: Checks: does the model reconcile?
A3: Test | B3: Result | C3: Detail
A4: Revenue per week is about £508m (Deliverable 4: £6.6bn ÷ 13) | B4: =IF(ABS(Inputs!D15-508)<1,"PASS","FAIL") -> PASS | C4: Inputs!D15
A5: Central do-nothing event loss = weeks x weekly profit + exceptional cost | B5: =IF(ABS(Model!B33-(Inputs!D9*Inputs!D15*Inputs!D8+Inputs!D16))<0.01,"PASS","FAIL") -> PASS | C5: Model central block
A6: Sensitivity grid agrees with Model for option B (15% probability, 2 weeks) | B6: =IF(ABS(Sensitivity!E7-Model!D42)<0.01,"PASS","FAIL") -> PASS | C6: Sensitivity!E7 vs Model
A7: All probabilities are between 0% and 100% | B7: =IF(AND(MIN(Inputs!C6:E7,Inputs!C24:F24)>=0,MAX(Inputs!C6:E7,Inputs!C24:F24)<=1),"PASS","FAIL") -> PASS | C7: Inputs rows 6, 7, 24
A8: Insurance recovery never exceeds the policy limit | B8: =IF(AND(Model!E34<=Inputs!E27,Model!F34<=Inputs!F27,Model!E11<=Inputs!E27,Model!F57<=Inputs!F27),"PASS","FAIL") -> PASS | C8: Model rows
A9: Net benefit = loss avoided minus cost for option D (central) | B9: =IF(ABS(Model!F42-(Model!F40-Inputs!F23))<0.01,"PASS","FAIL") -> PASS | C9: Model central block
A11: Overall | B11: =IF(COUNTIF(B4:B9,"PASS")=6,"ALL CHECKS PASS","CHECK FAILED") -> ALL CHECKS PASS

Sheet Sources
A1: Sources for fixed facts (numbers match the Source Log, Deliverable 1)
A3: Ref | B3: Fact used | C3: Source
A4: [7] | B4: Q2 FY26 results summary (loss, exceptional items) | C4: JLR results summary, JEC, Nov 2025
A5: [8] | B5: CMC £1.9bn, about 5,000 UK organisations | C5: Infosecurity Magazine, Oct 2025
A6: [9] | B6: CMC cost borne by supply chain | C6: Computing, Oct 2025
A7: [10] | B7: NCSC incident counts | C7: NCSC Annual Review 2025
A8: [20] | B8: FY25 profit before tax £2.5bn | C8: JLR FY25 results release (Automotive World)
A9: [23] | B9: Q2 FY26 volumes | C9: Automotive World, Oct 2025
A10: [24] | B10: Q3 FY26 volumes | C10: JLR Q3 sales release
A11: [25] | B11: Q2 revenue | C11: Yahoo Finance, Nov 2025
A12: [26] | B12: FY26 financials: £260m exceptional cyber cost, liquidity £6.9bn | C12: JLR Annual Report 2025/26, 21 May 2026
A13: [28] | B13: No cyber policy in force; none of £260m recovered; M&S £100m cover vs about £300m hit | C13: Insurance Business UK, 7 Sep 2026
A14: [29] | B14: Norsk Hydro first payout about 6% of losses | C14: Computing, 29 Oct 2019
A15: [30] | B15: Maersk rebuilt in 10 days | C15: Supply Chain Dive, 29 Jan 2018
